Workbook

Sheet NOTES_AND_TO_DO_LIST
B3: Notes and future implementation
B4: C'è una formattazione condizionale che se scrivo "Y" su una carta che ho mette in grassetto tutta la riga e cosi sulla base di questo template sono stati copiati tutti i singoli sheet per ogni set
B5: Messo un ritorno all'indice principale su ogni foglio e copiato come template. La forma della freccia è un collegamento ipertestuale all'indice nel foglio base ed è agganciata alla cella L4 per tutti i fogli. Infatti, alla scheda "Inserisci" selezionando la forma da aggiungere al foglio di lavoro, facendo click con il tasto destro sulla forma e selezionando "Formato forma", nella finestra di dialogo che si apre, andando alla sezione "Proprietà", selezionare l'opzione "Sposta e ridimensiona con le celle". In questo modo, la forma rimarrà agganciata alla cella specifica e si sposterà o ridimensionerà insieme alla cella quando si apportano modifiche al foglio di lavoro.
B6: Implementato che è stato messo tutto come formato testo sui numeri delle carte, altrimenti come formato "Generale" su Excel se metto robe come 1/64 o 2/64 (esempio su Jungle) le interpreta come date e scrive "gen-64" anche se il formato cella è "Generale"
B7: Implementato un check: se in ogni foglio corrispondente ogni carta ha "Y" sulla colonna "yes/no" allora nella colonna E dell'indice principale scrive "COMPLETE" altrimenti scrive "to be completed"
B8: implementare tutte le regole sopra anche su la parte di EX SERIES e VS set
B9: inserire tutti i set jappo, catalogarli eccc
B10: finire di inserire i set principali
B11: Sulla formula che fa il check del completamento nell'index principale non gli piace gli spazi nel nome del foglio singolo (esempio BASE_SET_2)
B12: fare una formattazione condizionale che se c'è "COMPLETE" mi mette in grassetto anche D5, C5, B5 (esempio) e così via per tutte le triplets di righe se invece c'è scritto "to be completed" mette in rosso il carattere di quella cella
B13: adattare le immagini alla dimensione di una cella E Agganciare le due immagini a fianco a quella cella (passare tutti i set per cui per ogni copia e incolla immagine faccio "INCOLLA IMMAGINE DENTRO LA CELLA") - COME FATTO SU EX RUBY E SAPPHIRE SIA PER LOGO CHE PER IMMAGINE SET
B14: Implementare tutto su un foglio a parte magari con CERCA VERT ecc.. Seguendo la timeline | - Original Era (1996 – 1999) https://pokumon.com/timeline/ - Neo Era (2000 – 2001) https://pokumon.com/timeline-neo-era/
... B18: La struttura è predisposta per l'integrazione ETL con CardTrader API: la colonna Condition è mappabile direttamente ai parametri dell'API, e Estimated Value è pronta a ricevere i prezzi normalizzati. la logica va implementata lato ETL (Extract, Transform, Load): si estraggono i prezzi da CardTrader via API, si normalizza la condizione con una funzione di mapping (ad esempio una tabella di lookup o una funzione CASE in SQL o equivalente in script), e si caricano i dati già armonizzati. Chiaramente non conviene fare questa traduzione direttamente in Excel se l’obiettivo è scalabilità e automazione

Sheet INDEX_TCG
B2: Un foglio di indice all'inizio della cartella di lavoro con collegamenti ipertestuali ai vari fogli (cliccando sul nome del set)
B4: WIZARD OF THE COAST | G4: VS ERA | L4: EX-SERIES
C5: BASE SET | D5: #VALUE! | E5: {=IF(COUNTIF(INDIRECT("BASE_SET!I6:I" & MAX(IF(BASE_SET!D:D<>"", ROW(BASE_SET!D:D)))), "Y") = MAX(IF(BASE_SET!D:D<>"", ROW(BASE_SET!D:D))) - 5, "COMPLETE", "to be completed")} -> COMPLETE | G5: #VALUE! | H5: Pokémon VS — minor expansion | I5: #VALUE! | J5: {=IF(COUNTIF(INDIRECT("'VS'!I6:I" & MAX(IF(VS!D:D<>"", ROW(VS!D:D)))), "Y") = MAX(IF(VS!D:D<>"", ROW(VS!D:D))) - 5, "COMPLETE", "to be completed")} -> to be completed | L5: #VALUE! | M5: EX Ruby & Sapphire | N5: #VALUE! | O5: {=IF(COUNTIF(INDIRECT("'EX_RUBY_SAPPHIRE'!I6:I" & MAX(IF(EX_RUBY_SAPPHIRE!D:D<>"", ROW(EX_RUBY_SAPPHIRE!D:D)))), "Y") = MAX(IF(EX_RUBY_SAPPHIRE!D:D<>"", ROW(EX_RUBY_SAPPHIRE!D:D))) - 5, "COMPLETE", "to be completed")} -> to be completed
B6: #VALUE! | C6: JUNGLE | D6: #VALUE! | E6: {=IF(COUNTIF(INDIRECT("'JUNGLE'!I6:I" & MAX(IF(JUNGLE!D:D<>"", ROW(JUNGLE!D:D)))), "Y") = MAX(IF(JUNGLE!D:D<>"", ROW(JUNGLE!D:D))) - 5, "COMPLETE", "to be completed")} -> to be completed | G6: VS PROMOTIONAL | L6: #VALUE! | M6: EX Sandstorm | N6: #VALUE! | O6: {=IF(COUNTIF(INDIRECT("'EX_SANDSTORM'!I6:I" & MAX(IF(EX_SANDSTORM!D:D<>"", ROW(EX_SANDSTORM!D:D)))), "Y") = MAX(IF(EX_SANDSTORM!D:D<>"", ROW(EX_SANDSTORM!D:D))) - 5, "COMPLETE", "to be completed")} -> to be completed
B7: #VALUE! | C7: FOSSIL | D7: #VALUE! | E7: {=IF(COUNTIF(INDIRECT("'FOSSIL'!I6:I" & MAX(IF(FOSSIL!D:D<>"", ROW(FOSSIL!D:D)))), "Y") = MAX(IF(FOSSIL!D:D<>"", ROW(FOSSIL!D:D))) - 5, "COMPLETE", "to be completed")} -> to be completed | H7: Theater Limited VS Pack | J7: {=IF(COUNTIF(INDIRECT("THEATER_LTD_VS_PACK!I6:I" & MAX(IF(THEATER_LTD_VS_PACK!D:D<>"", ROW(THEATER_LTD_VS_PACK!D:D)))), "Y") = MAX(IF(THEATER_LTD_VS_PACK!D:D<>"", ROW(THEATER_LTD_VS_PACK!D:D))) - 5, "COMPLETE", "to be completed")} -> to be completed | L7: #VALUE! | M7: EX Dragon | N7: #VALUE! | O7: {=IF(COUNTIF(INDIRECT("'EX_DRAGON'!I6:I" & MAX(IF(EX_DRAGON!D:D<>"", ROW(EX_DRAGON!D:D)))), "Y") = MAX(IF(EX_DRAGON!D:D<>"", ROW(EX_DRAGON!D:D))) - 5, "COMPLETE", "to be completed")} -> to be completed
B8: #VALUE! | C8: BASE SET 2 | D8: #VALUE! | E8: {=IF(COUNTIF(INDIRECT("'BASE_SET_2'!I6:I" & MAX(IF(BASE_SET_2!D:D<>"", ROW(BASE_SET_2!D:D)))), "Y") = MAX(IF(BASE_SET_2!D:D<>"", ROW(BASE_SET_2!D:D))) - 5, "COMPLETE", "to be completed")} -> to be completed | H8: Movie Commemoration VS Pack Sky-Splitting Deoxys (TCG) | J8: {=IF(COUNTIF(INDIRECT("MOVIE_VS_DEOXYS!I6:I" & MAX(IF(MOVIE_VS_DEOXYS!D:D<>"", ROW(MOVIE_VS_DEOXYS!D:D)))), "Y") = MAX(IF(MOVIE_VS_DEOXYS!D:D<>"", ROW(MOVIE_VS_DEOXYS!D:D))) - 5, "COMPLETE", "to be completed")} -> to be completed | L8: #VALUE! | M8: EX Team Magma vs Team Aqua | N8: #VALUE! | O8: {=IF(COUNTIF(INDIRECT("'EX_TEAM_MAGMA_ACQUA'!I6:I" & MAX(IF(EX_TEAM_MAGMA_ACQUA!D:D<>"", ROW(EX_TEAM_MAGMA_ACQUA!D:D)))), "Y") = MAX(IF(EX_TEAM_MAGMA_ACQUA!D:D<>"", ROW(EX_TEAM_MAGMA_ACQUA!D:D))) - 5, "COMPLETE", "to be completed")} -> to be completed
B9: #VALUE! | C9: TEAM ROCKET | D9: #VALUE! | E9: {=IF(COUNTIF(INDIRECT("'TEAM_ROCKET'!I6:I" & MAX(IF(TEAM_ROCKET!D:D<>"", ROW(TEAM_ROCKET!D:D)))), "Y") = MAX(IF(TEAM_ROCKET!D:D<>"", ROW(TEAM_ROCKET!D:D))) - 5, "COMPLETE", "to be completed")} -> to be completed | H9: Movie Commemoration VS Pack Aura's Lucario (TCG) | J9: {=IF(COUNTIF(INDIRECT("MOVIE_VS_LUCARIO!I6:I" & MAX(IF(MOVIE_VS_LUCARIO!D:D<>"", ROW(MOVIE_VS_LUCARIO!D:D)))), "Y") = MAX(IF(MOVIE_VS_LUCARIO!D:D<>"", ROW(MOVIE_VS_LUCARIO!D:D))) - 5, "COMPLETE", "to be completed")} -> to be completed | L9: #VALUE! | M9: EX Hidden Legends | N9: #VALUE! | O9: {=IF(COUNTIF(INDIRECT("'EX_HIDDEN_LEGENDS'!I6:I" & MAX(IF(EX_HIDDEN_LEGENDS!D:D<>"", ROW(EX_HIDDEN_LEGENDS!D:D)))), "Y") = MAX(IF(EX_HIDDEN_LEGENDS!D:D<>"", ROW(EX_HIDDEN_LEGENDS!D:D))) - 5, "COMPLETE", "to be completed")} -> to be completed
B10: #VALUE! | C10: GYM HEROES | D10: #VALUE! | E10: {=IF(COUNTIF(INDIRECT("'GYM_HEROES'!I6:I" & MAX(IF(GYM_HEROES!D:D<>"", ROW(GYM_HEROES!D:D)))), "Y") = MAX(IF(GYM_HEROES!D:D<>"", ROW(GYM_HEROES!D:D))) - 5, "COMPLETE", "to be completed")} -> to be completed | H10: Best of Game | J10: {=IF(COUNTIF(INDIRECT("BEST_OF_GAME!I6:I" & MAX(IF(BEST_OF_GAME!D:D<>"", ROW(BEST_OF_GAME!D:D)))), "Y") = MAX(IF(BEST_OF_GAME!D:D<>"", ROW(BEST_OF_GAME!D:D))) - 5, "COMPLETE", "to be completed")} -> to be completed | L10: #VALUE! | M10: EX FireRed & LeafGreen | N10: #VALUE! | O10: {=IF(COUNTIF(INDIRECT("'EX_FIRERED_LEAFGREEN'!I6:I" & MAX(IF(EX_FIRERED_LEAFGREEN!D:D<>"", ROW(EX_FIRERED_LEAFGREEN!D:D)))), "Y") = MAX(IF(EX_FIRERED_LEAFGREEN!D:D<>"", ROW(EX_FIRERED_LEAFGREEN!D:D))) - 5, "COMPLETE", "to be completed")} -> to be completed
B11: #VALUE! | C11: GYM CHALLENGE | D11: #VALUE! | E11: {=IF(COUNTIF(INDIRECT("'GYM_CHALLENGE'!I6:I" & MAX(IF(GYM_CHALLENGE!D:D<>"", ROW(GYM_CHALLENGE!D:D)))), "Y") = MAX(IF(GYM_CHALLENGE!D:D<>"", ROW(GYM_CHALLENGE!D:D))) - 5, "COMPLETE", "to be completed")} -> to be completed | L11: #VALUE! | M11: EX Team Rocket Returns | N11: #VALUE! | O11: {=IF(COUNTIF(INDIRECT("'EX_TEAM_ROCKET_RETURNS'!I6:I" & MAX(IF(EX_TEAM_ROCKET_RETURNS!D:D<>"", ROW(EX_TEAM_ROCKET_RETURNS!D:D)))), "Y") = MAX(IF(EX_TEAM_ROCKET_RETURNS!D:D<>"", ROW(EX_TEAM_ROCKET_RETURNS!D:D))) - 5, "COMPLETE", "to be completed")} -> to be completed
B12: #VALUE! | C12: NEO GENESIS | D12: #VALUE! | E12: {=IF(COUNTIF(INDIRECT("'NEO_GENESIS'!I6:I" & MAX(IF(NEO_GENESIS!D:D<>"", ROW(NEO_GENESIS!D:D)))), "Y") = MAX(IF(NEO_GENESIS!D:D<>"", ROW(NEO_GENESIS!D:D))) - 5, "COMPLETE", "to be completed")} -> to be completed | G12: UNNUMBERED PROMOTIONAL CARDS 1996-2005 | L12: #VALUE! | M12: EX Deoxys | N12: #VALUE! | O12: {=IF(COUNTIF(INDIRECT("'EX_DEOXYS'!I6:I" & MAX(IF(EX_DEOXYS!D:D<>"", ROW(EX_DEOXYS!D:D)))), "Y") = MAX(IF(EX_DEOXYS!D:D<>"", ROW(EX_DEOXYS!D:D))) - 5, "COMPLETE", "to be completed")} -> to be completed
B13: #VALUE! | C13: NEO DISCOVERY | D13: #VALUE! | E13: {=IF(COUNTIF(INDIRECT("'NEO_DISCOVERY'!I6:I" & MAX(IF(NEO_DISCOVERY!D:D<>"", ROW(NEO_DISCOVERY!D:D)))), "Y") = MAX(IF(NEO_DISCOVERY!D:D<>"", ROW(NEO_DISCOVERY!D:D))) - 5, "COMPLETE", "to be completed")} -> to be completed | H13: All Nippon Airlines "Get in a Jet! Double Chance Campaign" (November 1-31, 1998) | J13: {=IF(COUNTIF(INDIRECT("ANA_CAMPAIGN!I6:I" & MAX(IF(ANA_CAMPAIGN!D:D<>"", ROW(ANA_CAMPAIGN!D:D)))), "Y") = MAX(IF(ANA_CAMPAIGN!D:D<>"", ROW(ANA_CAMPAIGN!D:D))) - 5, "COMPLETE", "to be completed")} -> to be completed | L13: #VALUE! | M13: EX Emerald | N13: #VALUE! | O13: {=IF(COUNTIF(INDIRECT("'EX_EMERALD'!I6:I" & MAX(IF(EX_EMERALD!D:D<>"", ROW(EX_EMERALD!D:D)))), "Y") = MAX(IF(EX_EMERALD!D:D<>"", ROW(EX_EMERALD!D:D))) - 5, "COMPLETE", "to be completed")} -> to be completed
B14: #VALUE! | C14: NEO REVELATION | D14: #VALUE! | E14: {=IF(COUNTIF(INDIRECT("'NEO_REVELATION'!I6:I" & MAX(IF(NEO_REVELATION!D:D<>"", ROW(NEO_REVELATION!D:D)))), "Y") = MAX(IF(NEO_REVELATION!D:D<>"", ROW(NEO_REVELATION!D:D))) - 5, "COMPLETE", "to be completed")} -> to be completed | H14: Masaki | J14: {=IF(COUNTIF(INDIRECT("MASAKI!I6:I" & MAX(IF(MASAKI!D:D<>"", ROW(MASAKI!D:D)))), "Y") = MAX(IF(MASAKI!D:D<>"", ROW(MASAKI!D:D))) - 5, "COMPLETE", "to be completed")} -> to be completed | L14: #VALUE! | M14: EX Unseen Forces | N14: #VALUE! | O14: {=IF(COUNTIF(INDIRECT("'EX_UNSEEN_FORCES'!I6:I" & MAX(IF(EX_UNSEEN_FORCES!D:D<>"", ROW(EX_UNSEEN_FORCES!D:D)))), "Y") = MAX(IF(EX_UNSEEN_FORCES!D:D<>"", ROW(EX_UNSEEN_FORCES!D:D))) - 5, "COMPLETE", "to be completed")} -> to be completed
B15: #VALUE! | C15: NEO DESTINY | D15: #VALUE! | E15: {=IF(COUNTIF(INDIRECT("'NEO_DESTINY'!I6:I" & MAX(IF(NEO_DESTINY!D:D<>"", ROW(NEO_DESTINY!D:D)))), "Y") = MAX(IF(NEO_DESTINY!D:D<>"", ROW(NEO_DESTINY!D:D))) - 5, "COMPLETE", "to be completed")} -> to be completed | H15: Unnumbered Owner | J15: {=IF(COUNTIF(INDIRECT("UNNUMBERED_OWNER!I6:I" & MAX(IF(UNNUMBERED_OWNER!D:D<>"", ROW(UNNUMBERED_OWNER!D:D)))), "Y") = MAX(IF(UNNUMBERED_OWNER!D:D<>"", ROW(UNNUMBERED_OWNER!D:D))) - 5, "COMPLETE", "to be completed")} -> to be completed | L15: #VALUE! | M15: EX Delta Species | N15: #VALUE! | O15: {=IF(COUNTIF(INDIRECT("'EX_DELTA_SPECIES'!I6:I" & MAX(IF(EX_DELTA_SPECIES!D:D<>"", ROW(EX_DELTA_SPECIES!D:D)))), "Y") = MAX(IF(EX_DELTA_SPECIES!D:D<>"", ROW(EX_DELTA_SPECIES!D:D))) - 5, "COMPLETE", "to be completed")} -> to be completed
B16: #VALUE! | C16: LEGENDARY COLLECTION | D16: #VALUE! | E16: {=IF(COUNTIF(INDIRECT("'LEGENDARY_COLLECTION'!I6:I" & MAX(IF(LEGENDARY_COLLECTION!D:D<>"", ROW(LEGENDARY_COLLECTION!D:D)))), "Y") = MAX(IF(LEGENDARY_COLLECTION!D:D<>"", ROW(LEGENDARY_COLLECTION!D:D))) - 5, "COMPLETE", "to be completed")} -> to be completed | L16: #VALUE! | M16: EX Legend Maker | N16: #VALUE! | O16: {=IF(COUNTIF(INDIRECT("'EX_LEGEND_MAKER'!I6:I" & MAX(IF(EX_LEGEND_MAKER!D:D<>"", ROW(EX_LEGEND_MAKER!D:D)))), "Y") = MAX(IF(EX_LEGEND_MAKER!D:D<>"", ROW(EX_LEGEND_MAKER!D:D))) - 5, "COMPLETE", "to be completed")} -> to be completed
B17: #VALUE! | C17: EXPEDITION | D17: #VALUE! | E17: {=IF(COUNTIF(INDIRECT("'EXPEDITION'!I6:I" & MAX(IF(EXPEDITION!D:D<>"", ROW(EXPEDITION!D:D)))), "Y") = MAX(IF(EXPEDITION!D:D<>"", ROW(EXPEDITION!D:D))) - 5, "COMPLETE", "to be completed")} -> to be completed | L17: #VALUE! | M17: EX Holon Phantoms | N17: #VALUE! | O17: {=IF(COUNTIF(INDIRECT("'EX_HOLON_PHANTOMS'!I6:I" & MAX(IF(EX_HOLON_PHANTOMS!D:D<>"", ROW(EX_HOLON_PHANTOMS!D:D)))), "Y") = MAX(IF(EX_HOLON_PHANTOMS!D:D<>"", ROW(EX_HOLON_PHANTOMS!D:D))) - 5, "COMPLETE", "to be completed")} -> to be completed
B18: #VALUE! | C18: ACQUAPOLIS | D18: #VALUE! | E18: {=IF(COUNTIF(INDIRECT("'ACQUAPOLIS'!I6:I" & MAX(IF(ACQUAPOLIS!D:D<>"", ROW(ACQUAPOLIS!D:D)))), "Y") = MAX(IF(ACQUAPOLIS!D:D<>"", ROW(ACQUAPOLIS!D:D))) - 5, "COMPLETE", "to be completed")} -> to be completed | L18: #VALUE! | M18: EX Crystal Guardians | N18: #VALUE! | O18: {=IF(COUNTIF(INDIRECT("'EX_CRYSTAL_GUARDIANS'!I6:I" & MAX(IF(EX_CRYSTAL_GUARDIANS!D:D<>"", ROW(EX_CRYSTAL_GUARDIANS!D:D)))), "Y") = MAX(IF(EX_CRYSTAL_GUARDIANS!D:D<>"", ROW(EX_CRYSTAL_GUARDIANS!D:D))) - 5, "COMPLETE", "to be completed")} -> to be completed
B19: #VALUE! | C19: SKYRIDGE | D19: #VALUE! | E19: {=IF(COUNTIF(INDIRECT("'SKYRIDGE'!I6:I" & MAX(IF(SKYRIDGE!D:D<>"", ROW(SKYRIDGE!D:D)))), "Y") = MAX(IF(SKYRIDGE!D:D<>"", ROW(SKYRIDGE!D:D))) - 5, "COMPLETE", "to be completed")} -> to be completed | L19: #VALUE! | M19: EX Dragon Frontiers | N19: #VALUE! | O19: {=IF(COUNTIF(INDIRECT("'EX_DRAGON_FRONTIERS'!I6:I" & MAX(IF(EX_DRAGON_FRONTIERS!D:D<>"", ROW(EX_DRAGON_FRONTIERS!D:D)))), "Y") = MAX(IF(EX_DRAGON_FRONTIERS!D:D<>"", ROW(EX_DRAGON_FRONTIERS!D:D))) - 5, "COMPLETE", "to be completed")} -> to be completed
B20: VENDING MACHINE CARDS | G20: CARDASS | L20: #VALUE! | M20: EX Power Keepers | N20: #VALUE! | O20: {=IF(COUNTIF(INDIRECT("'EX_POWER_KEEPERS'!I6:I" & MAX(IF(EX_POWER_KEEPERS!D:D<>"", ROW(EX_POWER_KEEPERS!D:D)))), "Y") = MAX(IF(EX_POWER_KEEPERS!D:D<>"", ROW(EX_POWER_KEEPERS!D:D))) - 5, "COMPLETE", "to be completed")} -> to be completed
B21: #VALUE! | C21: Vending Machine cards Series 1 (Blue) | D21: 拡張シート | E21: {=IF(COUNTIF(INDIRECT("'VMC_SERIES1_BLUE'!I6:I" & MAX(IF(VMC_SERIES1_BLUE!D:D<>"", ROW(VMC_SERIES1_BLUE!D:D)))), "Y") = MAX(IF(VMC_SERIES1_BLUE!D:D<>"", ROW(VMC_SERIES1_BLUE!D:D))) - 5, "COMPLETE", "to be completed")} -> to be completed | H21: Pocket Monsters Carddass Trading Cards | J21: {=IF(COUNTIF(INDIRECT("PM_CARDDASS!I6:I" & MAX(IF(PM_CARDDASS!D:D<>"", ROW(PM_CARDDASS!D:D)))), "Y") = MAX(IF(PM_CARDDASS!D:D<>"", ROW(PM_CARDDASS!D:D))) - 5, "COMPLETE", "to be completed")} -> to be completed
B22: #VALUE! | C22: Vending Machine cards Series 2 (Red) | D22: 拡張シート | E22: =IF(COUNTIF(VMC_SERIES2_RED!I6:I500,"Y")=COUNTA(VMC_SERIES2_RED!D6:D500),"COMPLETE","to be completed") -> to be completed
B23: #VALUE! | C23: Vending Machine cards Series 3 (Green) | D23: 拡張シート | E23: =IF(COUNTIF(VMC_SERIES3_GREEN!I6:I500,"Y")=COUNTA(VMC_SERIES3_GREEN!D6:D500),"COMPLETE","to be completed") -> to be completed
B24: WOC PROMOTIONAL SERIES
B25: #VALUE! | C25: Southern Islands | D25: #VALUE! | E25: {=IF(COUNTIF(INDIRECT("'SOUTHERN_ISLAND'!I6:I" & MAX(IF(SOUTHERN_ISLAND!D:D<>"", ROW(SOUTHERN_ISLAND!D:D)))), "Y") = MAX(IF(SOUTHERN_ISLAND!D:D<>"", ROW(SOUTHERN_ISLAND!D:D))) - 5, "COMPLETE", "to be completed")} -> to be completed
B26: #VALUE! | C26: Wizards Black Star Promos | E26: {=IF(COUNTIF(INDIRECT("'WOC_PROMO'!I6:I" & MAX(IF(WOC_PROMO!D:D<>"", ROW(WOC_PROMO!D:D)))), "Y") = MAX(IF(WOC_PROMO!D:D<>"", ROW(WOC_PROMO!D:D))) - 5, "COMPLETE", "to be completed")} -> to be completed

Sheet PROMO

Sheet SOUTHERN_ISLAND
B2: HOME | C2: Link | D2: https://bulbapedia.bulbagarden.net/wiki/Southern_Islands_(TCG)
C3: Card set name | D3: Southern Islands (TCG)
C5: Rarity | D5: No. | E5: Card name | F5: Type | G5: Promotion | H5: Quantity | I5: yes/no | J5: Language | K5: 1st edition | L5: Stamped | M5: Reverse Holo | N5: Condition | O5: Estimated Value | P5: Notes
C6: - | D6: 1/18 | E6: Mew | F6: Psychic | G6: Sky (Rainbow Island) | H6: -
C7: - | D7: 2/18 | E7: Pidgeot | F7: Colorless | G7: Sky (Rainbow Island) | H7: -
C8: - | D8: 3/18 | E8: Onix | F8: Fighting | G8: Sky (Rainbow Island) | H8: -
C9: - | D9: 4/18 | E9: Togepi | F9: Colorless | G9: Riverside (Rainbow Island) | H9: - | I9: Y
C10: - | D10: 5/18 | E10: Ivysaur | F10: Grass | G10: Riverside (Rainbow Island) | H10: -
C11: - | D11: 6/18 | E11: Raticate | F11: Colorless | G11: Riverside (Rainbow Island) | H11: -
C12: - | D12: 7/18 | E12: Ledyba | F12: Grass | G12: Field of Flowers (Rainbow Island) | H12: - | I12: Y
C13: - | D13: 8/18 | E13: Jigglypuff | F13: Colorless | G13: Field of Flowers (Rainbow Island) | H13: -
C14: - | D14: 9/18 | E14: Butterfree | F14: Grass | G14: Field of Flowers (Rainbow Island) | H14: -
C15: - | D15: 10/18 | E15: Tentacruel | F15: Water | G15: Sea (Tropical Island) | H15: -
C16: - | D16: 11/18 | E16: Marill | F16: Water | G16: Sea (Tropical Island) | H16: - | I16: Y
C17: - | D17: 12/18 | E17: Lapras | F17: Water | G17: Sea (Tropical Island) | H17: - | I17: Y
C18: - | D18: 13/18 | E18: Exeggutor | F18: Grass | G18: Beach (Tropical Island) | H18: -
C19: - | D19: 14/18 | E19: Slowking | F19: Psychic | G19: Beach (Tropical Island) | H19: -
C20: - | D20: 15/18 | E20: Wartortle | F20: Water | G20: Beach (Tropical Island) | H20: - | I20: Y
C21: - | D21: 16/18 | E21: Lickitung | F21: Colorless | G21: Jungle (Tropical Island) | H21: -
C22: - | D22: 17/18 | E22: Vileplume | F22: Grass | G22: Jungle (Tropical Island) | H22: -
C23: - | D23: 18/18 | E23: Primeape | F23: Fighting | G23: Jungle (Tropical Island) | H23: -

Sheet WOC_PROMO
B2: HOME | C2: Link | D2: https://bulbapedia.bulbagarden.net/wiki/Wizards_Black_Star_Promos_(TCG)
C3: Card set name | D3: Wizards Black Star Promos (TCG)
C5: Rarity | D5: No. | E5: Card name | F5: Type | G5: Promotion | H5: Quantity | I5: yes/no | J5: Language | K5: 1st edition | L5: Stamped | M5: Reverse Holo | N5: Condition | O5: Estimated Value | P5: Notes
C6: - | D6: 1 | E6: Pikachu | F6: Lightning | G6: Pokémon League (July 1999) | H6: - | I6: Y
C7: - | D7: 2 | E7: Electabuzz [Pokémon: The First Movie] | F7: Lightning | G7: Mewtwo Strikes Back theatrical release (November 12, 1999) | H7: - | I7: Y
C8: - | D8: 3 | E8: Mewtwo [Pokémon: The First Movie] | F8: Psychic | G8: Mewtwo Strikes Back theatrical release (November 12, 1999) | H8: - | I8: Y
C9: - | D9: 4 | E9: Pikachu [Pokémon: The First Movie] | F9: Lightning | G9: Mewtwo Strikes Back theatrical release (November 12, 1999) | H9: - | I9: Y
C10: - | D10: 5 | E10: Dragonite [Pokémon: The First Movie] | F10: Colorless | G10: Mewtwo Strikes Back theatrical release (November 12, 1999) | H10: - | I10: Y
C11: - | D11: 6 | E11: Arcanine | F11: Fire | G11: Pokémon League (March 2000) | H11: - | I11: Y
C12: - | D12: 7 | E12: Jigglypuff | F12: Colorless | G12: Pokémon: The First Movie Soundtrack (November 9, 1999) | H12: - | I12: Y
C13: - | D13: 8 | E13: Mew | F13: Psychic | G13: Pokémon League (January 2000) | H13: - | I13: Y
C14: - | D14: 9 | E14: Mew | F14: Psychic | G14: Pokémon League (April 2000) | H14: -
C15: - | D15: 10 | E15: Meowth | F15: Colorless | G15: Pokémon Trading Card Game (Game Boy) (April 7, 2000) | H15: - | I15: Y
C16: - | D16: 11 | E16: Eevee | F16: Colorless | G16: Pokémon League (June 2000) | H16: -
C17: - | D17: 12 | E17: Mewtwo | F17: Psychic | G17: Nintendo Power Magazine (April 2000) | H17: -
C18: - | D18: 13 | E18: Venusaur | F18: Grass | G18: Pokémon Trading Card Game: Official Nintendo Player's Guide (March 31, 2000) | H18: -
C19: - | D19: 14 | E19: Mewtwo | F19: Psychic | G19: Mewtwo Strikes Back Home video release (March 21, 2000) | H19: - | I19: Y
C20: - | D20: 15 | E20: Cool Porygon | F20: Colorless | G20: Pokémon Stadium Nintendo 64 Bundle (February 2000) | H20: - | I20: Y
C21: - | D21: 16 | E21: Computer Error | F21: T [R] | G21: Pokémon League (May 2000) | H21: - | I21: Y
C22: - | D22: 17 | E22: Dark Persian | F22: Colorless | G22: Nintendo Power Magazine (August 2000) | H22: - | I22: Y
C23: - | D23: 18 | E23: Team Rocket's Meowth | F23: Colorless | G23: Pokémon League (August 2000) | H23: -
C24: - | D24: 19 | E24: Sabrina's Abra | F24: Psychic | G24: Nintendo Power Magazine (October 2000) | H24: - | I24: Y
C25: - | D25: 20 | E25: Psyduck | F25: Water | G25: Pokémon League (September 2000) | H25: -
C26: - | D26: 21 | E26: Moltres | F26: Fire | G26: The Power of One theatrical release (July 21, 2000) | H26: - | I26: Y
C27: - | D27: 22 | E27: Articuno | F27: Water | G27: The Power of One theatrical release (July 21, 2000) | H27: - | I27: Y
C28: - | D28: 23 | E28: Zapdos | F28: Lightning | G28: The Power of One theatrical release (July 21, 2000) | H28: - | I28: Y
C29: - | D29: 24 | E29: _____'s Pikachu | F29: Lightning | G29: Pokémon League "Create-a-Card" Activity (January 6, 2001) | H29: -
C30: - | D30: 25 | E30: Flying Pikachu | F30: Lightning | G30: Pokémon League (August 2001) | H30: -
C31: - | D31: 26 | E31: Pikachu | F31: Lightning | G31: Pokémon League (August 2001) | H31: - | I31: Y
C32: - | D32: 27 | E32: Pikachu | F32: Lightning | G32: The Power of One Home video release (November 14, 2000) | H32: - | I32: Y
C33: - | D33: 28 | E33: Surfing Pikachu | F33: Lightning | G33: Pokémon League (August 2001) | H33: -
C34: - | D34: 29 | E34: Marill | F34: Water | G34: Pokémon League (December 2000) | H34: - | I34: Y
C35: - | D35: 30 | E35: Togepi | F35: Colorless | G35: Pokémon League (January 2001) | H35: - | I35: Y
C36: - | D36: 31 | E36: Cleffa | F36: Colorless | G36: Pokémon League (February 2001) | H36: - | I36: Y
C37: - | D37: 32 | E37: Smeargle | F37: Colorless | G37: Pokémon League (March 2001) | H37: - | I37: Y
C38: - | D38: 33 | E38: Scizor | F38: Metal | G38: Pokémon League (June 2001) | H38: - | I38: Y
C39: - | D39: 34 | E39: Entei | F39: Fire | G39: Spell of the Unown: Entei theatrical release (April 6, 2001) | H39: - | I39: Y
C40: - | D40: 35 | E40: Pichu | F40: Lightning | G40: Pokémon League (April 2001) | H40: - | I40: Y
C41: - | D41: 36 | E41: Igglybuff | F41: Colorless | G41: Pokémon League (May 2001) | H41: - | I41: Y
C42: - | D42: 37 | E42: Hitmontop | F42: Fighting | G42: Pokémon League (July 2001) | H42: - | I42: Y
...

Sheet VENDING_MACHINE_CARDS

Sheet VMC_SERIES1_BLUE
B2: HOME | C2: Link | D2: https://bulbapedia.bulbagarden.net/wiki/Vending_Machine_cards_(TCG)#Vending_Machine_cards_Series_1_(Blue)
C3: Card set name | D3: Vending Machine cards Series 1 (Blue)
C5: Rarity | D5: No. | E5: Card name | F5: Type | G5: Promotion | H5: Quantity | I5: yes/no | J5: Language | K5: 1st edition | L5: Stamped | M5: Reverse Holo | N5: Condition | O5: Estimated Value | P5: Notes
C6: Uncommon | D6: — | E6: Bulbasaur | F6: Grass | G6: - | H6: -
C7: Common | D7: — | E7: Caterpie | F7: Grass | G7: - | H7: -
C8: Uncommon | D8: — | E8: Metapod | F8: Grass | G8: - | H8: -
C9: Common | D9: — | E9: Weedle | F9: Grass | G9: - | H9: -
C10: Common | D10: — | E10: Kakuna | F10: Grass | G10: - | H10: -
C11: Common | D11: — | E11: Nidoran♀ | F11: Grass | G11: - | H11: -
C12: Common | D12: — | E12: Nidoran♂ | F12: Grass | G12: - | H12: -
C13: Common | D13: — | E13: Zubat | F13: Grass | G13: - | H13: -
C14: Common | D14: — | E14: Golbat | F14: Grass | G14: - | H14: -
C15: Common | D15: — | E15: Paras | F15: Grass | G15: - | H15: -
C16: Common | D16: — | E16: Parasect | F16: Grass | G16: - | H16: -
C17: Uncommon | D17: — | E17: Pinsir | F17: Grass | G17: - | H17: -
... C41: — | D41: — | E41: Fossil Excavation | F41: T | G41: - | H41: -

Sheet VMC_SERIES2_RED
B2: HOME | C2: Link | D2: https://bulbapedia.bulbagarden.net/wiki/Vending_Machine_cards_(TCG)#Vending_Machine_cards_Series_2_(Red)
C3: Card set name | D3: Vending Machine cards Series 2 (Red)
C5: Rarity | D5: No. | E5: Card name | F5: Type | G5: Promotion | H5: Quantity | I5: yes/no | J5: Language | K5: 1st edition | L5: Stamped | M5: Reverse Holo | N5: Condition | O5: Estimated Value | P5: Notes
C6: Common | D6: 1/105 | E6: Lorem Ipsum | F6: Colorless | G6: - | H6: - | I6: N
C7: Common | D7: 2/105 | E7: Lorem Ipsum | F7: Colorless | G7: - | H7: - | I7: N
C8: Common | D8: 3/105 | E8: Lorem Ipsum | F8: Colorless | G8: - | H8: - | I8: N
C9: Common | D9: 4/105 | E9: Lorem Ipsum | F9: Colorless | G9: - | H9: - | I9: N
C10: Common | D10: 5/105 | E10: Lorem Ipsum | F10: Colorless | G10: - | H10: - | I10: N
C11: Common | D11: 6/105 | E11: Lorem Ipsum | F11: Colorless | G11: - | H11: - | I11: N
C12: Common | D12: 7/105 | E12: Lorem Ipsum | F12: Colorless | G12: - | H12: - | I12: N
C13: Common | D13: 8/105 | E13: Lorem Ipsum | F13: Colorless | G13: - | H13: - | I13: N
C14: Common | D14: 9/105 | E14: Lorem Ipsum | F14: Colorless | G14: - | H14: - | I14: N
C15: Common | D15: 10/105 | E15: Lorem Ipsum | F15: Colorless | G15: - | H15: - | I15: N
C16: Common | D16: 11/105 | E16: Lorem Ipsum | F16: Colorless | G16: - | H16: - | I16: N
C17: Common | D17: 12/105 | E17: Lorem Ipsum | F17: Colorless | G17: - | H17: - | I17: N
... C22: Common | D22: 17/105 | E22: Lorem Ipsum | F22: Colorless | G22: - | H22: - | I22: N

Sheet VMC_SERIES3_GREEN
B2: HOME | C2: Link | D2: https://bulbapedia.bulbagarden.net/wiki/Vending_Machine_cards_(TCG)#Vending_Machine_cards_Series_3_(Green)
C3: Card set name | D3: Vending Machine cards Series 3 (Green)
C5: Rarity | D5: No. | E5: Card name | F5: Type | G5: Promotion | H5: Quantity | I5: yes/no | J5: Language | K5: 1st edition | L5: Stamped | M5: Reverse Holo | N5: Condition | O5: Estimated Value | P5: Notes
C6: Common | D6: 1/105 | E6: Lorem Ipsum | F6: Colorless | G6: - | H6: - | I6: N
C7: Common | D7: 2/105 | E7: Lorem Ipsum | F7: Colorless | G7: - | H7: - | I7: N
C8: Common | D8: 3/105 | E8: Lorem Ipsum | F8: Colorless | G8: - | H8: - | I8: N
C9: Common | D9: 4/105 | E9: Lorem Ipsum | F9: Colorless | G9: - | H9: - | I9: N
C10: Common | D10: 5/105 | E10: Lorem Ipsum | F10: Colorless | G10: - | H10: - | I10: N
C11: Common | D11: 6/105 | E11: Lorem Ipsum | F11: Colorless | G11: - | H11: - | I11: N
C12: Common | D12: 7/105 | E12: Lorem Ipsum | F12: Colorless | G12: - | H12: - | I12: N
C13: Common | D13: 8/105 | E13: Lorem Ipsum | F13: Colorless | G13: - | H13: - | I13: N
C14: Common | D14: 9/105 | E14: Lorem Ipsum | F14: Colorless | G14: - | H14: - | I14: N
C15: Common | D15: 10/105 | E15: Lorem Ipsum | F15: Colorless | G15: - | H15: - | I15: N
C16: Common | D16: 11/105 | E16: Lorem Ipsum | F16: Colorless | G16: - | H16: - | I16: N
C17: Common | D17: 12/105 | E17: Lorem Ipsum | F17: Colorless | G17: - | H17: - | I17: N
... C22: Common | D22: 17/105 | E22: Lorem Ipsum | F22: Colorless | G22: - | H22: - | I22: N

Sheet WOC

Sheet BASE_SET
B2: HOME | C2: Link | D2: https://bulbapedia.bulbagarden.net/wiki/Base_Set_(TCG)
C3: Card set name | D3: BASE SET
C5: Rarity | D5: No. | E5: Card name | F5: Type | G5: Promotion | H5: Quantity | I5: yes/no | J5: Language | K5: 1st edition | L5: Stamped | M5: Reverse Holo | N5: Condition | O5: Estimated Value | P5: Notes
C6: Rare Holo | D6: 1/102 | E6: Alakazam | F6: Psychic | G6: - | H6: - | I6: Y
C7: Rare Holo | D7: 2/102 | E7: Blastoise | F7: Water | G7: - | H7: - | I7: Y
C8: Rare Holo | D8: 3/102 | E8: Chansey | F8: Colorless | G8: - | H8: - | I8: Y
C9: Rare Holo | D9: 4/102 | E9: Charizard | F9: Fire | G9: - | H9: - | I9: Y
C10: Rare Holo | D10: 5/102 | E10: Clefairy | F10: Colorless | G10: - | H10: - | I10: Y
C11: Rare Holo | D11: 6/102 | E11: Gyarados | F11: Water | G11: - | H11: - | I11: Y
C12: Rare Holo | D12: 7/102 | E12: Hitmonchan | F12: Fighting | G12: - | H12: - | I12: Y
C13: Rare Holo | D13: 8/102 | E13: Machamp | F13: Fighting | G13: - | H13: - | I13: Y
C14: Rare Holo | D14: 9/102 | E14: Magneton | F14: Lightning | G14: - | H14: - | I14: Y
C15: Rare Holo | D15: 10/102 | E15: Mewtwo | F15: Psychic | G15: - | H15: - | I15: Y
C16: Rare Holo | D16: 11/102 | E16: Nidoking | F16: Grass | G16: - | H16: - | I16: Y
C17: Rare Holo | D17: 12/102 | E17: Ninetales | F17: Fire | G17: - | H17: - | I17: Y
... C107: — | D107: 102/102 | E107: Water Energy | F107: Water E | G107: - | H107: - | I107: Y

Sheet JUNGLE
B2: HOME | C2: Link | D2: https://bulbapedia.bulbagarden.net/wiki/Jungle_(TCG)
C3: Card set name | D3: JUNGLE
C5: Rarity | D5: No. | E5: Card name | F5: Type | G5: Promotion | H5: Quantity | I5: yes/no | J5: Language | K5: 1st edition | L5: Stamped | M5: Reverse Holo | N5: Condition | O5: Estimated Value | P5: Notes
C6: Rare Holo | D6: 1/64 | E6: Clefable | F6: Colorless | G6: - | H6: - | I6: Y
C7: Rare Holo | D7: 2/64 | E7: Electrode | F7: Lightning | G7: - | H7: - | I7: Y
C8: Rare Holo | D8: 3/64 | E8: Flareon | F8: Fire | G8: - | H8: -
C9: Rare Holo | D9: 4/64 | E9: Jolteon | F9: Lightning | G9: - | H9: -
C10: Rare Holo | D10: 5/64 | E10: Kangaskhan | F10: Colorless | G10: - | H10: - | I10: Y
C11: Rare Holo | D11: 6/64 | E11: Mr. Mime | F11: Psychic | G11: - | H11: -
C12: Rare Holo | D12: 7/64 | E12: Nidoqueen | F12: Grass | G12: - | H12: - | I12: Y
C13: Rare Holo | D13: 8/64 | E13: Pidgeot | F13: Colorless | G13: - | H13: -
C14: Rare Holo | D14: 9/64 | E14: Pinsir | F14: Grass | G14: - | H14: -
C15: Rare Holo | D15: 10/64 | E15: Scyther | F15: Grass | G15: - | H15: - | I15: Y
C16: Rare Holo | D16: 11/64 | E16: Snorlax | F16: Colorless | G16: - | H16: -
C17: Rare Holo | D17: 12/64 | E17: Vaporeon | F17: Water | G17: - | H17: - | I17: Y
C18: Rare Holo | D18: 13/64 | E18: Venomoth | F18: Grass | G18: - | H18: - | I18: Y
C19: Rare Holo | D19: 14/64 | E19: Victreebel | F19: Grass | G19: - | H19: -
C20: Rare Holo | D20: 15/64 | E20: Vileplume | F20: Grass | G20: - | H20: -
C21: Rare Holo | D21: 16/64 | E21: Wigglytuff | F21: Colorless | G21: - | H21: - | I21: Y
C22: Rare | D22: 17/64 | E22: Clefable | F22: Colorless | G22: - | H22: - | I22: Y
C23: Rare | D23: 18/64 | E23: Electrode | F23: Lightning | G23: - | H23: - | I23: Y
C24: Rare | D24: 19/64 | E24: Flareon | F24: Fire | G24: - | H24: - | I24: Y
C25: Rare | D25: 20/64 | E25: Jolteon | F25: Lightning | G25: - | H25: - | I25: Y
C26: Rare | D26: 21/64 | E26: Kangaskhan | F26: Colorless | G26: - | H26: - | I26: Y
C27: Rare | D27: 22/64 | E27: Mr. Mime | F27: Psychic | G27: - | H27: - | I27: Y
C28: Rare | D28: 23/64 | E28: Nidoqueen | F28: Grass | G28: - | H28: - | I28: Y
C29: Rare | D29: 24/64 | E29: Pidgeot | F29: Colorless | G29: - | H29: - | I29: Y
C30: Rare | D30: 25/64 | E30: Pinsir | F30: Grass | G30: - | H30: - | I30: Y
C31: Rare | D31: 26/64 | E31: Scyther | F31: Grass | G31: - | H31: - | I31: Y
C32: Rare | D32: 27/64 | E32: Snorlax | F32: Colorless | G32: - | H32: - | I32: Y
... C34: Rare | D34: 29/64 | E34: Venomoth | F34: Grass | G34: - | H34: - | I34: Y
C35: Rare | D35: 30/64 | E35: Victreebel | F35: Grass | G35: - | H35: -
C36: Rare | D36: 31/64 | E36: Vileplume | F36: Grass | G36: - | H36: - | I36: Y
C37: Rare | D37: 32/64 | E37: Wigglytuff | F37: Colorless | G37: - | H37: - | I37: Y
C38: Uncommon | D38: 33/64 | E38: Butterfree | F38: Grass | G38: - | H38: - | I38: Y
C39: Uncommon | D39: 34/64 | E39: Dodrio | F39: Colorless | G39: - | H39: - | I39: Y
C40: Uncommon | D40: 35/64 | E40: Exeggutor | F40: Grass | G40: - | H40: - | I40: Y
C41: Uncommon | D41: 36/64 | E41: Fearow | F41: Colorless | G41: - | H41: - | I41: Y
C42: Uncommon | D42: 37/64 | E42: Gloom | F42: Grass | G42: - | H42: - | I42: Y
C43: Uncommon | D43: 38/64 | E43: Lickitung | F43: Colorless | G43: - | H43: - | I43: Y
...

Sheet FOSSIL
B2: HOME | C2: Link | D2: https://bulbapedia.bulbagarden.net/wiki/Fossil_(TCG)
C3: Card set name | D3: FOSSIL
C5: Rarity | D5: No. | E5: Card name | F5: Type | G5: Promotion | H5: Quantity | I5: yes/no | J5: Language | K5: 1st edition | L5: Stamped | M5: Reverse Holo | N5: Condition | O5: Estimated Value | P5: Notes
C6: Rare Holo | D6: 1/62 | E6: Aerodactyl | F6: Fighting | G6: - | H6: - | I6: Y
C7: Rare Holo | D7: 2/62 | E7: Articuno | F7: Water | G7: - | H7: -
C8: Rare Holo | D8: 3/62 | E8: Ditto | F8: Colorless | G8: - | H8: -
C9: Rare Holo | D9: 4/62 | E9: Dragonite | F9: Colorless | G9: - | H9: - | I9: Y
C10: Rare Holo | D10: 5/62 | E10: Gengar | F10: Psychic | G10: - | H10: - | I10: Y
C11: Rare Holo | D11: 6/62 | E11: Haunter | F11: Psychic | G11: - | H11: -
C12: Rare Holo | D12: 7/62 | E12: Hitmonlee | F12: Fighting | G12: - | H12: -
C13: Rare Holo | D13: 8/62 | E13: Hypno | F13: Psychic | G13: - | H13: - | I13: Y
C14: Rare Holo | D14: 9/62 | E14: Kabutops | F14: Fighting | G14: - | H14: - | I14: Y
C15: Rare Holo | D15: 10/62 | E15: Lapras | F15: Water | G15: - | H15: - | I15: Y
C16: Rare Holo | D16: 11/62 | E16: Magneton | F16: Lightning | G16: - | H16: -
C17: Rare Holo | D17: 12/62 | E17: Moltres | F17: Fire | G17: - | H17: - | I17: Y
C18: Rare Holo | D18: 13/62 | E18: Muk | F18: Grass | G18: - | H18: - | I18: Y
C19: Rare Holo | D19: 14/62 | E19: Raichu | F19: Lightning | G19: - | H19: -
C20: Rare Holo | D20: 15/62 | E20: Zapdos | F20: Lightning | G20: - | H20: -
C21: Rare | D21: 16/62 | E21: Aerodactyl | F21: Fighting | G21: - | H21: - | I21: Y
C22: Rare | D22: 17/62 | E22: Articuno | F22: Water | G22: - | H22: - | I22: Y
C23: Rare | D23: 18/62 | E23: Ditto | F23: Colorless | G23: - | H23: - | I23: Y
C24: Rare | D24: 19/62 | E24: Dragonite | F24: Colorless | G24: - | H24: - | I24: Y
C25: Rare | D25: 20/62 | E25: Gengar | F25: Psychic | G25: - | H25: - | I25: Y
C26: Rare | D26: 21/62 | E26: Haunter | F26: Psychic | G26: - | H26: -
C27: Rare | D27: 22/62 | E27: Hitmonlee | F27: Fighting | G27: - | H27: - | I27: Y
C28: Rare | D28: 23/62 | E28: Hypno | F28: Psychic | G28: - | H28: - | I28: Y
C29: Rare | D29: 24/62 | E29: Kabutops | F29: Fighting | G29: - | H29: - | I29: Y
C30: Rare | D30: 25/62 | E30: Lapras | F30: Water | G30: - | H30: - | I30: Y
C31: Rare | D31: 26/62 | E31: Magneton | F31: Lightning | G31: - | H31: -
C32: Rare | D32: 27/62 | E32: Moltres | F32: Fire | G32: - | H32: - | I32: Y
C33: Rare | D33: 28/62 | E33: Muk | F33: Grass | G33: - | H33: - | I33: Y
C34: Rare | D34: 29/62 | E34: Raichu | F34: Lightning | G34: - | H34: - | I34: Y
C35: Rare | D35: 30/62 | E35: Zapdos | F35: Lightning | G35: - | H35: - | I35: Y
C36: Uncommon | D36: 31/62 | E36: Arbok | F36: Grass | G36: - | H36: - | I36: Y
C37: Uncommon | D37: 32/62 | E37: Cloyster | F37: Water | G37: - | H37: - | I37: Y
C38: Uncommon | D38: 33/62 | E38: Gastly | F38: Psychic | G38: - | H38: - | I38: Y
C39: Uncommon | D39: 34/62 | E39: Golbat | F39: Grass | G39: - | H39: - | I39: Y
C40: Uncommon | D40: 35/62 | E40: Golduck | F40: Water | G40: - | H40: - | I40: Y
C41: Uncommon | D41: 36/62 | E41: Golem | F41: Fighting | G41: - | H41: - | I41: Y
C42: Uncommon | D42: 37/62 | E42: Graveler | F42: Fighting | G42: - | H42: - | I42: Y
...

Sheet BASE_SET_2
B2: HOME | C2: Link | D2: https://bulbapedia.bulbagarden.net/wiki/Base_Set_2_(TCG)
C3: Card set name | D3: BASE SET 2
C5: Rarity | D5: No. | E5: Card name | F5: Type | G5: Promotion | H5: Quantity | I5: yes/no | J5: Language | K5: 1st edition | L5: Stamped | M5: Reverse Holo | N5: Condition | O5: Estimated Value | P5: Notes
C6: Rare Holo | D6: 1/130 | E6: Alakazam | F6: Psychic | G6: - | H6: -
C7: Rare Holo | D7: 2/130 | E7: Blastoise | F7: Water | G7: - | H7: -
C8: Rare Holo | D8: 3/130 | E8: Chansey | F8: Colorless | G8: - | H8: -
C9: Rare Holo | D9: 4/130 | E9: Charizard | F9: Fire | G9: - | H9: -
C10: Rare Holo | D10: 5/130 | E10: Clefable | F10: Colorless | G10: - | H10: -
C11: Rare Holo | D11: 6/130 | E11: Clefairy | F11: Colorless | G11: - | H11: -
C12: Rare Holo | D12: 7/130 | E12: Gyarados | F12: Water | G12: - | H12: -
C13: Rare Holo | D13: 8/130 | E13: Hitmonchan | F13: Fighting | G13: - | H13: -
C14: Rare Holo | D14: 9/130 | E14: Magneton | F14: Lightning | G14: - | H14: -
C15: Rare Holo | D15: 10/130 | E15: Mewtwo | F15: Psychic | G15: - | H15: -
C16: Rare Holo | D16: 11/130 | E16: Nidoking | F16: Grass | G16: - | H16: -
C17: Rare Holo | D17: 12/130 | E17: Nidoqueen | F17: Grass | G17: - | H17: -
... C30: Rare | D30: 25/130 | E30: Electrode | F30: Lightning | G30: - | H30: -
B31: 1UW1H27001361 | C31: Rare | D31: 26/130 | E31: Kangaskhan | F31: Colorless | G31: - | H31: - | I31: Y
C32: Rare | D32: 27/130 | E32: Mr. Mime | F32: Psychic | G32: - | H32: -
C33: Rare | D33: 28/130 | E33: Pidgeotto | F33: Colorless | G33: - | H33: -
C34: Rare | D34: 29/130 | E34: Pinsir | F34: Grass | G34: - | H34: -
C35: Rare | D35: 30/130 | E35: Snorlax | F35: Colorless | G35: - | H35: -
C36: Rare | D36: 31/130 | E36: Venomoth | F36: Grass | G36: - | H36: -
B37: 1UW1H27001361 | C37: Rare | D37: 32/130 | E37: Victreebel | F37: Grass | G37: - | H37: - | I37: Y
C38: Uncommon | D38: 33/130 | E38: Arcanine | F38: Fire | G38: - | H38: -
C39: Uncommon | D39: 34/130 | E39: Butterfree | F39: Grass | G39: - | H39: -
C40: Uncommon | D40: 35/130 | E40: Charmeleon | F40: Fire | G40: - | H40: -
C41: Uncommon | D41: 36/130 | E41: Dewgong | F41: Water | G41: - | H41: -
C42: Uncommon | D42: 37/130 | E42: Dodrio | F42: Colorless | G42: - | H42: -
C43: Uncommon | D43: 38/130 | E43: Dratini | F43: Colorless | G43: - | H43: -
C44: Uncommon | D44: 39/130 | E44: Exeggutor | F44: Grass | G44: - | H44: -
C45: Uncommon | D45: 40/130 | E45: Farfetch'd | F45: Colorless | G45: - | H45: -
C46: Uncommon | D46: 41/130 | E46: Fearow | F46: Colorless | G46: - | H46: -
C47: Uncommon | D47: 42/130 | E47: Growlithe | F47: Fire | G47: - | H47: -
C48: Uncommon | D48: 43/130 | E48: Haunter | F48: Psychic | G48: - | H48: -
C49: Uncommon | D49: 44/130 | E49: Ivysaur | F49: Grass | G49: - | H49: -
... C53: Uncommon | D53: 48/130 | E53: Lickitung | F53: Colorless | G53: - | H53: -
B54: 1UW1H27001361 | C54: Uncommon | D54: 49/130 | E54: Machoke | F54: Fighting | G54: - | H54: - | I54: Y
C55: Uncommon | D55: 50/130 | E55: Magikarp | F55: Water | G55: - | H55: -
C56: Uncommon | D56: 51/130 | E56: Magmar | F56: Fire | G56: - | H56: -
C57: Uncommon | D57: 52/130 | E57: Marowak | F57: Fighting | G57: - | H57: -
...

Sheet TEAM_ROCKET
B2: HOME | C2: Link | D2: https://bulbapedia.bulbagarden.net/wiki/Team_Rocket_(TCG)
C3: Card set name | D3: TEAM ROCKET
C5: Rarity | D5: No. | E5: Card name | F5: Type | G5: Promotion | H5: Quantity | I5: yes/no | J5: Language | K5: 1st edition | L5: Stamped | M5: Reverse Holo | N5: Condition | O5: Estimated Value | P5: Notes
C6: Rare Holo | D6: 1/82 | E6: Dark Alakazam | F6: Psychic | G6: - | H6: -
C7: Rare Holo | D7: 2/82 | E7: Dark Arbok | F7: Grass | G7: - | H7: - | I7: Y
C8: Rare Holo | D8: 3/82 | E8: Dark Blastoise | F8: Water | G8: - | H8: -
C9: Rare Holo | D9: 4/82 | E9: Dark Charizard | F9: Fire | G9: - | H9: -
C10: Rare Holo | D10: 5/82 | E10: Dark Dragonite | F10: Colorless | G10: - | H10: -
C11: Rare Holo | D11: 6/82 | E11: Dark Dugtrio | F11: Fighting | G11: - | H11: - | I11: Y
C12: Rare Holo | D12: 7/82 | E12: Dark Golbat | F12: Grass | G12: - | H12: -
C13: Rare Holo | D13: 8/82 | E13: Dark Gyarados | F13: Water | G13: - | H13: -
C14: Rare Holo | D14: 9/82 | E14: Dark Hypno | F14: Psychic | G14: - | H14: -
C15: Rare Holo | D15: 10/82 | E15: Dark Machamp | F15: Fighting | G15: - | H15: - | I15: Y
C16: Rare Holo | D16: 11/82 | E16: Dark Magneton | F16: Lightning | G16: - | H16: -
C17: Rare Holo | D17: 12/82 | E17: Dark Slowbro | F17: Psychic | G17: - | H17: -
C18: Rare Holo | D18: 13/82 | E18: Dark Vileplume | F18: Grass | G18: - | H18: -
C19: Rare Holo | D19: 14/82 | E19: Dark Weezing | F19: Grass | G19: - | H19: - | I19: Y
C20: Rare Holo | D20: 15/82 | E20: Here Comes Team Rocket! | F20: T | G20: - | H20: -
C21: Rare Holo | D21: 16/82 | E21: Rocket's Sneak Attack | F21: T | G21: - | H21: -
C22: Rare Holo | D22: 17/82 | E22: Rainbow Energy | F22: Rainbow E | G22: - | H22: -
C23: Rare | D23: 18/82 | E23: Dark Alakazam | F23: Psychic | G23: - | H23: - | I23: Y
C24: Rare | D24: 19/82 | E24: Dark Arbok | F24: Grass | G24: - | H24: - | I24: Y
C25: Rare | D25: 20/82 | E25: Dark Blastoise | F25: Water | G25: - | H25: - | I25: Y
C26: Rare | D26: 21/82 | E26: Dark Charizard | F26: Fire | G26: - | H26: -
C27: Rare | D27: 22/82 | E27: Dark Dragonite | F27: Colorless | G27: - | H27: - | I27: Y
C28: Rare | D28: 23/82 | E28: Dark Dugtrio | F28: Fighting | G28: - | H28: - | I28: Y
C29: Rare | D29: 24/82 | E29: Dark Golbat | F29: Grass | G29: - | H29: - | I29: Y
C30: Rare | D30: 25/82 | E30: Dark Gyarados | F30: Water | G30: - | H30: - | I30: Y
C31: Rare | D31: 26/82 | E31: Dark Hypno | F31: Psychic | G31: - | H31: - | I31: Y
C32: Rare | D32: 27/82 | E32: Dark Machamp | F32: Fighting | G32: - | H32: - | I32: Y
C33: Rare | D33: 28/82 | E33: Dark Magneton | F33: Lightning | G33: - | H33: - | I33: Y
C34: Rare | D34: 29/82 | E34: Dark Slowbro | F34: Psychic | G34: - | H34: - | I34: Y
C35: Rare | D35: 30/82 | E35: Dark Vileplume | F35: Grass | G35: - | H35: - | I35: Y
B36: 20083310160 | C36: Rare | D36: 31/82 | E36: Dark Weezing | F36: Grass | G36: - | H36: - | I36: Y
C37: Uncommon | D37: 32/82 | E37: Dark Charmeleon | F37: Fire | G37: - | H37: - | I37: Y
C38: Uncommon | D38: 33/82 | E38: Dark Dragonair | F38: Colorless | G38: - | H38: - | I38: Y
C39: Uncommon | D39: 34/82 | E39: Dark Electrode | F39: Lightning | G39: - | H39: - | I39: Y
C40: Uncommon | D40: 35/82 | E40: Dark Flareon | F40: Fire | G40: - | H40: - | I40: Y
C41: Uncommon | D41: 36/82 | E41: Dark Gloom | F41: Grass | G41: - | H41: - | I41: Y
C42: Uncommon | D42: 37/82 | E42: Dark Golduck | F42: Water | G42: - | H42: - | I42: Y
...

Sheet GYM_HEROES
B2: HOME | C2: Link | D2: https://bulbapedia.bulbagarden.net/wiki/Gym_Heroes_(TCG)
C3: Card set name | D3: GYM HEROES
C5: Rarity | D5: No. | E5: Card name | F5: Type | G5: Promotion | H5: Quantity | I5: yes/no | J5: Language | K5: 1st edition | L5: Stamped | M5: Reverse Holo | N5: Condition | O5: Estimated Value | P5: Notes
C6: Rare Holo | D6: 1/132 | E6: Blaine's Moltres | F6: Fire | G6: - | H6: - | I6: Y | J6: English
C7: Rare Holo | D7: 2/132 | E7: Brock's Rhydon | F7: Fighting | G7: - | H7: - | I7: Y | J7: English
C8: Rare Holo | D8: 3/132 | E8: Erika's Clefable | F8: Colorless | G8: - | H8: - | I8: Y | J8: English
C9: Rare Holo | D9: 4/132 | E9: Erika's Dragonair | F9: Colorless | G9: - | H9: - | I9: Y | J9: English
C10: Rare Holo | D10: 5/132 | E10: Erika's Vileplume | F10: Grass | G10: - | H10: - | I10: Y | J10: English
C11: Rare Holo | D11: 6/132 | E11: Lt. Surge's Electabuzz | F11: Lightning | G11: - | H11: - | I11: Y | J11: English
C12: Rare Holo | D12: 7/132 | E12: Lt. Surge's Fearow | F12: Colorless | G12: - | H12: - | I12: Y | J12: English
C13: Rare Holo | D13: 8/132 | E13: Lt. Surge's Magneton | F13: Lightning | G13: - | H13: - | I13: Y | J13: English
C14: Rare Holo | D14: 9/132 | E14: Misty's Seadra | F14: Water | G14: - | H14: - | I14: Y | J14: English
C15: Rare Holo | D15: 10/132 | E15: Misty's Tentacruel | F15: Water | G15: - | H15: - | I15: Y | J15: English
C16: Rare Holo | D16: 11/132 | E16: Rocket's Hitmonchan | F16: Fighting | G16: - | H16: - | I16: Y | J16: English
C17: Rare Holo | D17: 12/132 | E17: Rocket's Moltres | F17: Fire | G17: - | H17: - | I17: Y | J17: English
C18: Rare Holo | D18: 13/132 | E18: Rocket's Scyther | F18: Grass | G18: - | H18: - | I18: Y | J18: English
C19: Rare Holo | D19: 14/132 | E19: Sabrina's Gengar | F19: Psychic | G19: - | H19: - | J19: English
C20: Rare Holo | D20: 15/132 | E20: Brock | F20: T | G20: - | H20: - | I20: Y | J20: English
C21: Rare Holo | D21: 16/132 | E21: Erika | F21: T | G21: - | H21: - | I21: Y | J21: English
C22: Rare Holo | D22: 17/132 | E22: Lt. Surge | F22: T | G22: - | H22: - | I22: Y | J22: English
C23: Rare Holo | D23: 18/132 | E23: Misty | F23: T | G23: - | H23: - | I23: Y | J23: English
C24: Rare Holo | D24: 19/132 | E24: The Rocket's Trap | F24: T | G24: - | H24: - | I24: Y | J24: English
C25: Rare | D25: 20/132 | E25: Brock's Golem | F25: Fighting | G25: - | H25: - | I25: Y | J25: English
C26: Rare | D26: 21/132 | E26: Brock's Onix | F26: Fighting | G26: - | H26: - | I26: Y | J26: English
C27: Rare | D27: 22/132 | E27: Brock's Rhyhorn | F27: Fighting | G27: - | H27: - | I27: Y | J27: English
C28: Rare | D28: 23/132 | E28: Brock's Sandslash | F28: Fighting | G28: - | H28: - | I28: Y | J28: English
C29: Rare | D29: 24/132 | E29: Brock's Zubat | F29: Grass | G29: - | H29: - | I29: Y | J29: English
C30: Rare | D30: 25/132 | E30: Erika's Clefairy | F30: Colorless | G30: - | H30: - | I30: Y | J30: English
C31: Rare | D31: 26/132 | E31: Erika's Victreebel | F31: Grass | G31: - | H31: - | I31: Y | J31: English
... C103: Rare | D103: 98/132 | E103: Brock | F103: T | G103: - | H103: - | I103: Y | J103: English
B104: 1UW1H27001361 | C104: Rare | D104: 99/132 | E104: Charity | F104: T | G104: - | H104: - | I104: Y | J104: English
C105: Rare | D105: 100/132 | E105: Erika | F105: T | G105: - | H105: - | I105: Y | J105: English
C106: Rare | D106: 101/132 | E106: Lt. Surge | F106: T | G106: - | H106: - | I106: Y | J106: English
C107: Rare | D107: 102/132 | E107: Misty | F107: T | G107: - | H107: - | I107: Y | J107: English
C108: Rare | D108: 103/132 | E108: No Removal Gym | F108: T [St] | G108: - | H108: - | J108: English
C109: Rare | D109: 104/132 | E109: The Rocket's Training Gym | F109: T [St] | G109: - | H109: - | I109: Y | J109: English
C110: Uncommon | D110: 105/132 | E110: Blaine's Last Resort | F110: T | G110: - | H110: - | I110: Y | J110: English
C111: Uncommon | D111: 106/132 | E111: Brock's Training Method | F111: T | G111: - | H111: - | I111: Y | J111: English
C112: Uncommon | D112: 107/132 | E112: Celadon City Gym | F112: T [St] | G112: - | H112: - | I112: Y | J112: English
C113: Uncommon | D113: 108/132 | E113: Cerulean City Gym | F113: T [St] | G113: - | H113: - | I113: Y | J113: English
...

Sheet GYM_CHALLENGE
B2: HOME | C2: Link | D2: https://bulbapedia.bulbagarden.net/wiki/Gym_Challenge_(TCG)
C3: Card set name | D3: GYM CHALLENGE
C5: Rarity | D5: No. | E5: Card name | F5: Type | G5: Promotion | H5: Quantity | I5: yes/no | J5: Language | K5: 1st edition | L5: Stamped | M5: Reverse Holo | N5: Condition | O5: Estimated Value | P5: Notes
C6: Rare Holo | D6: 1/132 | E6: Blaine's Arcanine | F6: Fire | G6: - | H6: - | I6: Y | J6: English
C7: Rare Holo | D7: 2/132 | E7: Blaine's Charizard | F7: Fire | G7: - | H7: - | J7: English
C8: Rare Holo | D8: 3/132 | E8: Brock's Ninetales | F8: Fire | G8: - | H8: - | I8: Y | J8: English
C9: Rare Holo | D9: 4/132 | E9: Erika's Venusaur | F9: Grass | G9: - | H9: - | J9: English
C10: Rare Holo | D10: 5/132 | E10: Giovanni's Gyarados | F10: Water | G10: - | H10: - | J10: English
C11: Rare Holo | D11: 6/132 | E11: Giovanni's Machamp | F11: Fighting | G11: - | H11: - | I11: Y | J11: English
C12: Rare Holo | D12: 7/132 | E12: Giovanni's Nidoking | F12: Grass | G12: - | H12: - | J12: English
C13: Rare Holo | D13: 8/132 | E13: Giovanni's Persian | F13: Colorless | G13: - | H13: - | I13: Y | J13: English
C14: Rare Holo | D14: 9/132 | E14: Koga's Beedrill | F14: Grass | G14: - | H14: - | I14: Y | J14: English
C15: Rare Holo | D15: 10/132 | E15: Koga's Ditto | F15: Colorless | G15: - | H15: - | I15: Y | J15: English
C16: Rare Holo | D16: 11/132 | E16: Lt. Surge's Raichu | F16: Lightning | G16: - | H16: - | J16: English
C17: Rare Holo | D17: 12/132 | E17: Misty's Golduck | F17: Water | G17: - | H17: - | I17: Y | J17: English
C18: Rare Holo | D18: 13/132 | E18: Misty's Gyarados | F18: Water | G18: - | H18: - | J18: English
C19: Rare Holo | D19: 14/132 | E19: Rocket's Mewtwo | F19: Psychic | G19: - | H19: - | J19: English
C20: Rare Holo | D20: 15/132 | E20: Rocket's Zapdos | F20: Lightning | G20: - | H20: - | I20: Y | J20: English
C21: Rare Holo | D21: 16/132 | E21: Sabrina's Alakazam | F21: Psychic | G21: - | H21: - | J21: English
C22: Rare Holo | D22: 17/132 | E22: Blaine | F22: T | G22: - | H22: - | I22: Y | J22: English
C23: Rare Holo | D23: 18/132 | E23: Giovanni | F23: T | G23: - | H23: - | I23: Y | J23: English
C24: Rare Holo | D24: 19/132 | E24: Koga | F24: T | G24: - | H24: - | I24: Y | J24: English
C25: Rare Holo | D25: 20/132 | E25: Sabrina | F25: T | G25: - | H25: - | J25: English
C26: Rare | D26: 21/132 | E26: Blaine's Ninetales | F26: Fire | G26: - | H26: - | I26: Y | J26: English
C27: Rare | D27: 22/132 | E27: Brock's Dugtrio | F27: Fighting | G27: - | H27: - | I27: Y | J27: English
C28: Rare | D28: 23/132 | E28: Giovanni's Nidoqueen | F28: Grass | G28: - | H28: - | I28: Y | J28: English
C29: Rare | D29: 24/132 | E29: Giovanni's Pinsir | F29: Grass | G29: - | H29: - | I29: Y | J29: English
C30: Rare | D30: 25/132 | E30: Koga's Arbok | F30: Grass | G30: - | H30: - | I30: Y | J30: English
C31: Rare | D31: 26/132 | E31: Koga's Muk | F31: Grass | G31: - | H31: - | I31: Y | J31: English
C32: Rare | D32: 27/132 | E32: Koga's Pidgeotto | F32: Colorless | G32: - | H32: - | I32: Y | J32: English
C33: Rare | D33: 28/132 | E33: Lt. Surge's Jolteon | F33: Lightning | G33: - | H33: - | J33: English
C34: Rare | D34: 29/132 | E34: Sabrina's Gengar | F34: Psychic | G34: - | H34: - | I34: Y | J34: English
C35: Rare | D35: 30/132 | E35: Sabrina's Golduck | F35: Water | G35: - | H35: - | I35: Y | J35: English
C36: Uncommon | D36: 31/132 | E36: Blaine's Charmeleon | F36: Fire | G36: - | H36: - | I36: Y | J36: English
C37: Uncommon | D37: 32/132 | E37: Blaine's Dodrio | F37: Colorless | G37: - | H37: - | I37: Y | J37: English
C38: Uncommon | D38: 33/132 | E38: Blaine's Rapidash | F38: Fire | G38: - | H38: - | I38: Y | J38: English
C39: Uncommon | D39: 34/132 | E39: Brock's Graveler | F39: Fighting | G39: - | H39: - | I39: Y | J39: English
C40: Uncommon | D40: 35/132 | E40: Brock's Primeape | F40: Fighting | G40: - | H40: - | I40: Y | J40: English
C41: Uncommon | D41: 36/132 | E41: Brock's Sandslash | F41: Fighting | G41: - | H41: - | I41: Y | J41: English
C42: Uncommon | D42: 37/132 | E42: Brock's Vulpix | F42: Fire | G42: - | H42: - | J42: English
...

Sheet NEO_GENESIS
B2: HOME | C2: Link | D2: https://bulbapedia.bulbagarden.net/wiki/Neo_Genesis_(TCG)
C3: Card set name | D3: NEO GENESIS
C5: Rarity | D5: No. | E5: Card name | F5: Type | G5: Promotion | H5: Quantity | I5: yes/no | J5: Language | K5: 1st edition | L5: Stamped | M5: Reverse Holo | N5: Condition | O5: Estimated Value | P5: Notes
C6: Rare Holo | D6: 1/111 | E6: Ampharos | F6: Lightning | G6: - | H6: - | I6: Y
C7: Rare Holo | D7: 2/111 | E7: Azumarill | F7: Water | G7: - | H7: - | I7: Y
C8: Rare Holo | D8: 3/111 | E8: Bellossom | F8: Grass | G8: - | H8: - | I8: Y
C9: Rare Holo | D9: 4/111 | E9: Feraligatr | F9: Water | G9: - | H9: -
C10: Rare Holo | D10: 5/111 | E10: Feraligatr | F10: Water | G10: - | H10: - | I10: Y
C11: Rare Holo | D11: 6/111 | E11: Heracross | F11: Grass | G11: - | H11: - | I11: Y
C12: Rare Holo | D12: 7/111 | E12: Jumpluff | F12: Grass | G12: - | H12: - | I12: Y
C13: Rare Holo | D13: 8/111 | E13: Kingdra | F13: Water | G13: - | H13: - | I13: Y
C14: Rare Holo | D14: 9/111 | E14: Lugia | F14: Colorless | G14: - | H14: -
C15: Rare Holo | D15: 10/111 | E15: Meganium | F15: Grass | G15: - | H15: - | I15: Y
C16: Rare Holo | D16: 11/111 | E16: Meganium | F16: Grass | G16: - | H16: - | I16: Y
C17: Rare Holo | D17: 12/111 | E17: Pichu | F17: Lightning | G17: - | H17: - | I17: Y
C18: Rare Holo | D18: 13/111 | E18: Skarmory | F18: Metal | G18: - | H18: - | I18: Y
C19: Rare Holo | D19: 14/111 | E19: Slowking | F19: Psychic | G19: - | H19: - | I19: Y
C20: Rare Holo | D20: 15/111 | E20: Steelix | F20: Metal | G20: - | H20: - | I20: Y
C21: Rare Holo | D21: 16/111 | E21: Togetic | F21: Colorless | G21: - | H21: - | I21: Y
C22: Rare Holo | D22: 17/111 | E22: Typhlosion | F22: Fire | G22: - | H22: - | I22: Y
C23: Rare Holo | D23: 18/111 | E23: Typhlosion | F23: Fire | G23: - | H23: - | I23: Y
C24: Rare Holo | D24: 19/111 | E24: Metal Energy | F24: Metal E | G24: - | H24: - | I24: Y
C25: Rare | D25: 20/111 | E25: Cleffa | F25: Colorless | G25: - | H25: - | I25: Y
C26: Rare | D26: 21/111 | E26: Donphan | F26: Fighting | G26: - | H26: - | I26: Y
... C116: — | D116: 111/111 | E116: Water Energy | F116: Water E | G116: - | H116: - | I116: Y

Sheet NEO_DISCOVERY
B2: HOME | C2: Link | D2: https://bulbapedia.bulbagarden.net/wiki/Neo_Discovery_(TCG)
C3: Card set name | D3: NEO DISCOVERY
C5: Rarity | D5: No. | E5: Card name | F5: Type | G5: Promotion | H5: Quantity | I5: yes/no | J5: Language | K5: 1st edition | L5: Stamped | M5: Reverse Holo | N5: Condition | O5: Estimated Value | P5: Notes
C6: Rare Holo | D6: 1/75 | E6: Espeon | F6: Psychic | G6: - | H6: - | I6: Y
C7: Rare Holo | D7: 2/75 | E7: Forretress | F7: Metal | G7: - | H7: -
C8: Rare Holo | D8: 3/75 | E8: Hitmontop | F8: Fighting | G8: - | H8: - | I8: Y
C9: Rare Holo | D9: 4/75 | E9: Houndoom | F9: Darkness | G9: - | H9: -
C10: Rare Holo | D10: 5/75 | E10: Houndour | F10: Fire | G10: - | H10: -
C11: Rare Holo | D11: 6/75 | E11: Kabutops | F11: Water | G11: - | H11: -
C12: Rare Holo | D12: 7/75 | E12: Magnemite | F12: Metal | G12: - | H12: -
C13: Rare Holo | D13: 8/75 | E13: Politoed | F13: Water | G13: - | H13: -
C14: Rare Holo | D14: 9/75 | E14: Poliwrath | F14: Fighting | G14: - | H14: -
C15: Rare Holo | D15: 10/75 | E15: Scizor | F15: Metal | G15: - | H15: - | I15: Y
C16: Rare Holo | D16: 11/75 | E16: Smeargle | F16: Colorless | G16: - | H16: -
C17: Rare Holo | D17: 12/75 | E17: Tyranitar | F17: Darkness | G17: - | H17: - | I17: Y
C18: Rare Holo | D18: 13/75 | E18: Umbreon | F18: Darkness | G18: - | H18: -
C19: Rare Holo | D19: 14/75 | E19: Unown A | F19: Psychic | G19: - | H19: - | I19: Y
C20: Rare Holo | D20: 15/75 | E20: Ursaring | F20: Colorless | G20: - | H20: - | I20: Y
C21: Rare Holo | D21: 16/75 | E21: Wobbuffet | F21: Psychic | G21: - | H21: -
C22: Rare Holo | D22: 17/75 | E22: Yanma | F22: Grass | G22: - | H22: -
C23: Rare | D23: 18/75 | E23: Beedrill | F23: Grass | G23: - | H23: - | I23: Y
C24: Rare | D24: 19/75 | E24: Butterfree | F24: Grass | G24: - | H24: - | I24: Y
C25: Rare | D25: 20/75 | E25: Espeon | F25: Psychic | G25: - | H25: - | I25: Y
C26: Rare | D26: 21/75 | E26: Forretress | F26: Metal | G26: - | H26: - | I26: Y
C27: Rare | D27: 22/75 | E27: Hitmontop | F27: Fighting | G27: - | H27: - | I27: Y
C28: Rare | D28: 23/75 | E28: Houndoom | F28: Darkness | G28: - | H28: - | I28: Y
C29: Rare | D29: 24/75 | E29: Houndour | F29: Fire | G29: - | H29: - | I29: Y
C30: Rare | D30: 25/75 | E30: Kabutops | F30: Water | G30: - | H30: - | I30: Y
C31: Rare | D31: 26/75 | E31: Magnemite | F31: Metal | G31: - | H31: - | I31: Y
C32: Rare | D32: 27/75 | E32: Politoed | F32: Water | G32: - | H32: - | I32: Y
C33: Rare | D33: 28/75 | E33: Poliwrath | F33: Fighting | G33: - | H33: - | I33: Y
C34: Rare | D34: 29/75 | E34: Scizor | F34: Metal | G34: - | H34: - | I34: Y
... C38: Rare | D38: 33/75 | E38: Unown A | F38: Psychic | G38: - | H38: - | I38: Y
B39: 1UW1H27001361 | C39: Rare | D39: 34/75 | E39: Ursaring | F39: Colorless | G39: - | H39: - | I39: Y
C40: Rare | D40: 35/75 | E40: Wobbuffet | F40: Psychic | G40: - | H40: - | I40: Y
B41: 1UW1H27001361 | C41: Rare | D41: 36/75 | E41: Yanma | F41: Grass | G41: - | H41: - | I41: Y
C42: Uncommon | D42: 37/75 | E42: Corsola | F42: Water | G42: - | H42: - | I42: Y
C43: Uncommon | D43: 38/75 | E43: Eevee | F43: Colorless | G43: - | H43: - | I43: Y
C44: Uncommon | D44: 39/75 | E44: Houndour | F44: Darkness | G44: - | H44: - | I44: Y
C45: Uncommon | D45: 40/75 | E45: Igglybuff | F45: Colorless | G45: - | H45: - | I45: Y
...

Sheet NEO_REVELATION
B2: HOME | C2: Link | D2: https://bulbapedia.bulbagarden.net/wiki/Neo_Revelation_(TCG)
C3: Card set name | D3: NEO REVELATION
C5: Rarity | D5: No. | E5: Card name | F5: Type | G5: Promotion | H5: Quantity | I5: yes/no | J5: Language | K5: 1st edition | L5: Stamped | M5: Reverse Holo | N5: Condition | O5: Estimated Value | P5: Notes
C6: Rare Holo | D6: 1/64 | E6: Ampharos | F6: Lightning | G6: - | H6: -
C7: Rare Holo | D7: 2/64 | E7: Blissey | F7: Colorless | G7: - | H7: -
C8: Rare Holo | D8: 3/64 | E8: Celebi | F8: Psychic | G8: - | H8: -
C9: Rare Holo | D9: 4/64 | E9: Crobat | F9: Grass | G9: - | H9: -
C10: Rare Holo | D10: 5/64 | E10: Delibird | F10: Colorless | G10: - | H10: -
C11: Rare Holo | D11: 6/64 | E11: Entei | F11: Fire | G11: - | H11: -
C12: Rare Holo | D12: 7/64 | E12: Ho-Oh | F12: Fire | G12: - | H12: -
C13: Rare Holo | D13: 8/64 | E13: Houndoom | F13: Darkness | G13: - | H13: -
C14: Rare Holo | D14: 9/64 | E14: Jumpluff | F14: Grass | G14: - | H14: -
C15: Rare Holo | D15: 10/64 | E15: Magneton | F15: Metal | G15: - | H15: -
C16: Rare Holo | D16: 11/64 | E16: Misdreavus | F16: Psychic | G16: - | H16: -
C17: Rare Holo | D17: 12/64 | E17: Porygon2 | F17: Colorless | G17: - | H17: - | I17: Y
C18: Rare Holo | D18: 13/64 | E18: Raikou | F18: Lightning | G18: - | H18: - | I18: Y
C19: Rare Holo | D19: 14/64 | E19: Suicune | F19: Water | G19: - | H19: -
C20: Rare | D20: 15/64 | E20: Aerodactyl | F20: Fighting | G20: - | H20: - | I20: Y
C21: Rare | D21: 16/64 | E21: Celebi | F21: Grass | G21: - | H21: - | I21: Y
C22: Rare | D22: 17/64 | E22: Entei | F22: Fire | G22: - | H22: -
C23: Rare | D23: 18/64 | E23: Ho-Oh | F23: Colorless | G23: - | H23: - | I23: Y
C24: Rare | D24: 19/64 | E24: Kingdra | F24: Water | G24: - | H24: - | I24: Y
C25: Rare | D25: 20/64 | E25: Lugia | F25: Psychic | G25: - | H25: - | I25: Y
C26: Rare | D26: 21/64 | E26: Raichu | F26: Lightning | G26: - | H26: - | I26: Y
C27: Rare | D27: 22/64 | E27: Raikou | F27: Lightning | G27: - | H27: - | I27: Y
C28: Rare | D28: 23/64 | E28: Skarmory | F28: Metal | G28: - | H28: - | I28: Y
C29: Rare | D29: 24/64 | E29: Sneasel | F29: Darkness | G29: - | H29: - | I29: Y
C30: Rare | D30: 25/64 | E30: Starmie | F30: Psychic | G30: - | H30: - | I30: Y
C31: Rare | D31: 26/64 | E31: Sudowoodo | F31: Fighting | G31: - | H31: - | I31: Y
C32: Rare | D32: 27/64 | E32: Suicune | F32: Water | G32: - | H32: - | I32: Y
C33: Uncommon | D33: 28/64 | E33: Flaaffy | F33: Lightning | G33: - | H33: - | I33: Y
C34: Uncommon | D34: 29/64 | E34: Golbat | F34: Grass | G34: - | H34: - | I34: Y
... C69: Common | D69: 64/64 | E69: Old Rod | F69: T | G69: - | H69: - | I69: Y
C70: SuperRare Holo | D70: 65/64 | E70: Shining Gyarados | F70: Water | G70: - | H70: -
C71: SuperRare Holo | D71: 66/64 | E71: Shining Magikarp | F71: Water | G71: - | H71: -

Sheet NEO_DESTINY
B2: HOME | C2: Link | D2: https://bulbapedia.bulbagarden.net/wiki/Neo_Destiny_(TCG)
C3: Card set name | D3: NEO DESTINY
C5: Rarity | D5: No. | E5: Card name | F5: Type | G5: Promotion | H5: Quantity | I5: yes/no | J5: Language | K5: 1st edition | L5: Stamped | M5: Reverse Holo | N5: Condition | O5: Estimated Value | P5: Notes
C6: Rare Holo | D6: 1/105 | E6: Dark Ampharos | F6: Lightning | G6: - | H6: -
C7: Rare Holo | D7: 2/105 | E7: Dark Crobat | F7: Grass | G7: - | H7: -
C8: Rare Holo | D8: 3/105 | E8: Dark Donphan | F8: Fighting | G8: - | H8: -
C9: Rare Holo | D9: 4/105 | E9: Dark Espeon | F9: Psychic | G9: - | H9: -
C10: Rare Holo | D10: 5/105 | E10: Dark Feraligatr | F10: Water | G10: - | H10: -
C11: Rare Holo | D11: 6/105 | E11: Dark Gengar | F11: Psychic | G11: - | H11: -
C12: Rare Holo | D12: 7/105 | E12: Dark Houndoom | F12: Fire | G12: - | H12: -
C13: Rare Holo | D13: 8/105 | E13: Dark Porygon2 | F13: Colorless | G13: - | H13: -
C14: Rare Holo | D14: 9/105 | E14: Dark Scizor | F14: Metal | G14: - | H14: -
C15: Rare Holo | D15: 10/105 | E15: Dark Typhlosion | F15: Fire | G15: - | H15: -
C16: Rare Holo | D16: 11/105 | E16: Dark Tyranitar | F16: Fighting | G16: - | H16: -
C17: Rare Holo | D17: 12/105 | E17: Light Arcanine | F17: Fire | G17: - | H17: -
C18: Rare Holo | D18: 13/105 | E18: Light Azumarill | F18: Water | G18: - | H18: - | I18: Y
C19: Rare Holo | D19: 14/105 | E19: Light Dragonite | F19: Colorless | G19: - | H19: -
C20: Rare Holo | D20: 15/105 | E20: Light Togetic | F20: Colorless | G20: - | H20: -
